<?xml version="1.0" ?>
<!-- =================================================================================== -->
<!-- |    This document was autogenerated by xacro from src/robot/urdf/robot_model.xacro | -->
<!-- |    EDITING THIS FILE BY HAND IS NOT RECOMMENDED                                 | -->
<!-- =================================================================================== -->
<robot name="robot_model">
  <link name="base_link"/>
  <link name="chassis-link">
    <visual>
      <origin rpy="0 0 0" xyz="0 0 0"/>
      <geometry>
        <box size="0.52 0.42 0.2"/>
      </geometry>
      <material name="brown">
        <color rgba="0.3 0 0.4 1"/>
      </material>
    </visual>
    <collision>
      <origin rpy="0 0 0" xyz="0 0 0"/>
      <geometry>
        <box size="0.52 0.42 0.2"/>
      </geometry>
    </collision>
    <inertial>
      <origin rpy="0 0 0" xyz="0 0 0"/>
      <mass value="0.4"/>
      <inertia ixx="0.007213333333333333" ixy="0.0" ixz="0.0" iyy="0.010346666666666667" iyz="0.0" izz="0.014893333333333333"/>
    </inertial>
  </link>
  <joint name="joint-base-chassis" type="fixed">
    <parent link="base_link"/>
    <child link="chassis-link"/>
    <origin rpy="0 0 0" xyz="0 0 0.1"/>
  </joint>
  <link name="front_left_wheel_link">
    <visual>
      <origin rpy="1.5708 0 0" xyz="0 0 0"/>
      <geometry>
        <cylinder length="0.04" radius="0.1"/>
      </geometry>
      <material name="dark_grey">
        <color rgba="0.15 0.15 0.15 1.0"/>
      </material>
    </visual>
    <collision>
      <origin rpy="1.5708 0 0" xyz="0 0 0"/>
      <geometry>
        <cylinder length="0.04" radius="0.1"/>
      </geometry>
    </collision>
    <inertial>
      <origin rpy="1.5708 0 0" xyz="0 0 0"/>
      <mass value="1.2"/>
      <inertia ixx="0.00316" ixy="0.0" ixz="0.0" iyy="0.00316" iyz="0.0" izz="0.006"/>
    </inertial>
  </link>
  <joint name="front_left_wheel_joint" type="continuous">
    <parent link="chassis-link"/>
    <child link="front_left_wheel_link"/>
    <origin rpy="0 0 0" xyz="0.17 0.23 -0.1"/>
    <axis xyz="0 1 0"/>
    <dynamics damping="0.2" friction="0.1"/>
  </joint>
  <link name="front_right_wheel_link">
    <visual>
      <origin rpy="1.5708 0 0" xyz="0 0 0"/>
      <geometry>
        <cylinder length="0.04" radius="0.1"/>
      </geometry>
      <material name="dark_grey">
        <color rgba="0.15 0.15 0.15 1.0"/>
      </material>
    </visual>
    <collision>
      <origin rpy="1.5708 0 0" xyz="0 0 0"/>
      <geometry>
        <cylinder length="0.04" radius="0.1"/>
      </geometry>
    </collision>
    <inertial>
      <origin rpy="1.5708 0 0" xyz="0 0 0"/>
      <mass value="1.2"/>
      <inertia ixx="0.00316" ixy="0.0" ixz="0.0" iyy="0.00316" iyz="0.0" izz="0.006"/>
    </inertial>
  </link>
  <joint name="front_right_wheel_joint" type="continuous">
    <parent link="chassis-link"/>
    <child link="front_right_wheel_link"/>
    <origin rpy="0 0 0" xyz="0.17 -0.23 -0.1"/>
    <axis xyz="0 1 0"/>
    <dynamics damping="0.2" friction="0.1"/>
  </joint>
  <link name="rear_left_wheel_link">
    <visual>
      <origin rpy="1.5708 0 0" xyz="0 0 0"/>
      <geometry>
        <cylinder length="0.04" radius="0.1"/>
      </geometry>
      <material name="dark_grey">
        <color rgba="0.15 0.15 0.15 1.0"/>
      </material>
    </visual>
    <collision>
      <origin rpy="1.5708 0 0" xyz="0 0 0"/>
      <geometry>
        <cylinder length="0.04" radius="0.1"/>
      </geometry>
    </collision>
    <inertial>
      <origin rpy="1.5708 0 0" xyz="0 0 0"/>
      <mass value="1.2"/>
      <inertia ixx="0.00316" ixy="0.0" ixz="0.0" iyy="0.00316" iyz="0.0" izz="0.006"/>
    </inertial>
  </link>
  <joint name="rear_left_wheel_joint" type="continuous">
    <parent link="chassis-link"/>
    <child link="rear_left_wheel_link"/>
    <origin rpy="0 0 0" xyz="-0.17 0.23 -0.1"/>
    <axis xyz="0 1 0"/>
    <dynamics damping="0.2" friction="0.1"/>
  </joint>
  <link name="rear_right_wheel_link">
    <visual>
      <origin rpy="1.5708 0 0" xyz="0 0 0"/>
      <geometry>
        <cylinder length="0.04" radius="0.1"/>
      </geometry>
      <material name="dark_grey">
        <color rgba="0.15 0.15 0.15 1.0"/>
      </material>
    </visual>
    <collision>
      <origin rpy="1.5708 0 0" xyz="0 0 0"/>
      <geometry>
        <cylinder length="0.04" radius="0.1"/>
      </geometry>
    </collision>
    <inertial>
      <origin rpy="1.5708 0 0" xyz="0 0 0"/>
      <mass value="1.2"/>
      <inertia ixx="0.00316" ixy="0.0" ixz="0.0" iyy="0.00316" iyz="0.0" izz="0.006"/>
    </inertial>
  </link>
  <joint name="rear_right_wheel_joint" type="continuous">
    <parent link="chassis-link"/>
    <child link="rear_right_wheel_link"/>
    <origin rpy="0 0 0" xyz="-0.17 -0.23 -0.1"/>
    <axis xyz="0 1 0"/>
    <dynamics damping="0.2" friction="0.1"/>
  </joint>
  <link name="torso_link">
    <visual>
      <origin rpy="0 0 0" xyz="0 0 0"/>
      <geometry>
        <box size="0.52 0.42 0.2"/>
      </geometry>
      <material name="silver">
        <color rgba="0.75 0.75 0.78 1.0"/>
      </material>
    </visual>
    <collision>
      <origin rpy="0 0 0" xyz="0 0 0"/>
      <geometry>
        <box size="0.52 0.42 0.2"/>
      </geometry>
    </collision>
    <inertial>
      <origin rpy="0 0 0" xyz="0 0 0"/>
      <mass value="6.0"/>
      <inertia ixx="0.1082" ixy="0.0" ixz="0.0" iyy="0.1552" iyz="0.0" izz="0.22339999999999996"/>
    </inertial>
  </link>
  <joint name="torso_joint" type="fixed">
    <parent link="chassis-link"/>
    <child link="torso_link"/>
    <origin rpy="0 0 0" xyz="0 0 0.2"/>
  </joint>
  <link name="face_panel_link">
    <visual>
      <origin rpy="0 0 0" xyz="0.265 0 0.05"/>
      <geometry>
        <box size="0.01 0.18 0.12"/>
      </geometry>
      <material name="face_black">
        <color rgba="0.05 0.05 0.08 1.0"/>
      </material>
    </visual>
    <collision>
      <origin rpy="0 0 0" xyz="0.265 0 0.05"/>
      <geometry>
        <box size="0.01 0.18 0.12"/>
      </geometry>
    </collision>
    <inertial>
      <origin rpy="0 0 0" xyz="0.265 0 0.05"/>
      <mass value="0.2"/>
      <inertia ixx="0.0007799999999999999" ixy="0.0" ixz="0.0" iyy="0.00024166666666666664" iyz="0.0" izz="0.0005416666666666668"/>
    </inertial>
  </link>
  <joint name="face_panel_joint" type="fixed">
    <parent link="torso_link"/>
    <child link="face_panel_link"/>
    <origin rpy="0 0 0" xyz="0 0 0"/>
  </joint>
  <link name="left_arm_mount_link">
    <visual>
      <origin rpy="0 0 0" xyz="0 0 0"/>
      <geometry>
        <box size="0.05 0.05 0.05"/>
      </geometry>
      <material name="mount_gray">
        <color rgba="0.45 0.45 0.45 1.0"/>
      </material>
    </visual>
    <collision>
      <origin rpy="0 0 0" xyz="0 0 0"/>
      <geometry>
        <box size="0.05 0.05 0.05"/>
      </geometry>
    </collision>
    <inertial>
      <origin rpy="0 0 0" xyz="0 0 0"/>
      <mass value="0.35"/>
      <inertia ixx="0.00014583333333333335" ixy="0.0" ixz="0.0" iyy="0.00014583333333333335" iyz="0.0" izz="0.00014583333333333335"/>
    </inertial>
  </link>
  <joint name="left_arm_mount_joint" type="fixed">
    <parent link="torso_link"/>
    <child link="left_arm_mount_link"/>
    <origin rpy="0 0 1.5708" xyz="0.0 0.235 0.07500000000000001"/>
  </joint>
  <link name="left_arm_upper_arm_link">
    <visual>
      <origin rpy="0 1.5708 0" xyz="0.11 0 0"/>
      <geometry>
        <cylinder length="0.22" radius="0.028"/>
      </geometry>
      <material name="arm_blue">
        <color rgba="0.18 0.42 0.78 1.0"/>
      </material>
    </visual>
    <collision>
      <origin rpy="0 1.5708 0" xyz="0.11 0 0"/>
      <geometry>
        <cylinder length="0.22" radius="0.028"/>
      </geometry>
    </collision>
    <inertial>
      <origin rpy="0 1.5708 0" xyz="0.11 0 0"/>
      <mass value="1.1"/>
      <inertia ixx="0.004652266666666667" ixy="0.0" ixz="0.0" iyy="0.004652266666666667" iyz="0.0" izz="0.00043120000000000007"/>
    </inertial>
  </link>
  <joint name="left_arm_shoulder_joint" type="revolute">
    <parent link="left_arm_mount_link"/>
    <child link="left_arm_upper_arm_link"/>
    <origin rpy="0 0 0" xyz="0.025 0 0"/>
    <axis xyz="0 1 0"/>
    <limit effort="22.0" lower="-1.57" upper="1.57" velocity="1.5"/>
    <dynamics damping="0.5" friction="0.12"/>
  </joint>
  <link name="left_arm_forearm_link">
    <visual>
      <origin rpy="0 1.5708 0" xyz="0.10 0 0"/>
      <geometry>
        <cylinder length="0.20" radius="0.024"/>
      </geometry>
      <material name="arm_cyan">
        <color rgba="0.15 0.7 0.8 1.0"/>
      </material>
    </visual>
    <collision>
      <origin rpy="0 1.5708 0" xyz="0.10 0 0"/>
      <geometry>
        <cylinder length="0.20" radius="0.024"/>
      </geometry>
    </collision>
    <inertial>
      <origin rpy="0 1.5708 0" xyz="0.10 0 0"/>
      <mass value="0.8"/>
      <inertia ixx="0.002781866666666667" ixy="0.0" ixz="0.0" iyy="0.002781866666666667" iyz="0.0" izz="0.00023040000000000002"/>
    </inertial>
  </link>
  <joint name="left_arm_elbow_joint" type="revolute">
    <parent link="left_arm_upper_arm_link"/>
    <child link="left_arm_forearm_link"/>
    <origin rpy="0 0 0" xyz="0.22 0 0"/>
    <axis xyz="0 1 0"/>
    <limit effort="18.0" lower="-2.355" upper="2.355" velocity="1.6"/>
    <dynamics damping="0.4" friction="0.10"/>
  </joint>
  <link name="left_arm_wrist_link">
    <visual>
      <origin rpy="0 1.5708 0" xyz="0.06 0 0"/>
      <geometry>
        <cylinder length="0.12" radius="0.018"/>
      </geometry>
      <material name="arm_blue"/>
    </visual>
    <collision>
      <origin rpy="0 1.5708 0" xyz="0.06 0 0"/>
      <geometry>
        <cylinder length="0.12" radius="0.018"/>
      </geometry>
    </collision>
    <inertial>
      <origin rpy="0 1.5708 0" xyz="0.06 0 0"/>
      <mass value="0.35"/>
      <inertia ixx="0.00044835" ixy="0.0" ixz="0.0" iyy="0.00044835" iyz="0.0" izz="5.669999999999999e-05"/>
    </inertial>
  </link>
  <joint name="left_arm_wrist_joint" type="revolute">
    <parent link="left_arm_forearm_link"/>
    <child link="left_arm_wrist_link"/>
    <origin rpy="0 0 0" xyz="0.20 0 0"/>
    <axis xyz="0 1 0"/>
    <limit effort="10.0" lower="-1.57" upper="1.57" velocity="2.0"/>
    <dynamics damping="0.25" friction="0.08"/>
  </joint>
  <link name="left_arm_magnet_link">
    <visual>
      <origin rpy="0 1.5708 0" xyz="0.02 0 0"/>
      <geometry>
        <cylinder length="0.03" radius="0.03"/>
      </geometry>
      <material name="magnet_red">
        <color rgba="0.78 0.12 0.12 1.0"/>
      </material>
    </visual>
    <collision>
      <origin rpy="0 1.5708 0" xyz="0.02 0 0"/>
      <geometry>
        <cylinder length="0.03" radius="0.03"/>
      </geometry>
    </collision>
    <inertial>
      <origin rpy="0 1.5708 0" xyz="0.02 0 0"/>
      <mass value="0.15"/>
      <inertia ixx="4.5e-05" ixy="0.0" ixz="0.0" iyy="4.5e-05" iyz="0.0" izz="6.749999999999999e-05"/>
    </inertial>
  </link>
  <joint name="left_arm_magnet_joint" type="fixed">
    <parent link="left_arm_wrist_link"/>
    <child link="left_arm_magnet_link"/>
    <origin rpy="0 0 0" xyz="0.12 0 0"/>
  </joint>
  <link name="right_arm_mount_link">
    <visual>
      <origin rpy="0 0 0" xyz="0 0 0"/>
      <geometry>
        <box size="0.05 0.05 0.05"/>
      </geometry>
      <material name="mount_gray">
        <color rgba="0.45 0.45 0.45 1.0"/>
      </material>
    </visual>
    <collision>
      <origin rpy="0 0 0" xyz="0 0 0"/>
      <geometry>
        <box size="0.05 0.05 0.05"/>
      </geometry>
    </collision>
    <inertial>
      <origin rpy="0 0 0" xyz="0 0 0"/>
      <mass value="0.35"/>
      <inertia ixx="0.00014583333333333335" ixy="0.0" ixz="0.0" iyy="0.00014583333333333335" iyz="0.0" izz="0.00014583333333333335"/>
    </inertial>
  </link>
  <joint name="right_arm_mount_joint" type="fixed">
    <parent link="torso_link"/>
    <child link="right_arm_mount_link"/>
    <origin rpy="0 0 -1.5708" xyz="0.0 -0.235 0.07500000000000001"/>
  </joint>
  <link name="right_arm_upper_arm_link">
    <visual>
      <origin rpy="0 1.5708 0" xyz="0.11 0 0"/>
      <geometry>
        <cylinder length="0.22" radius="0.028"/>
      </geometry>
      <material name="arm_blue">
        <color rgba="0.18 0.42 0.78 1.0"/>
      </material>
    </visual>
    <collision>
      <origin rpy="0 1.5708 0" xyz="0.11 0 0"/>
      <geometry>
        <cylinder length="0.22" radius="0.028"/>
      </geometry>
    </collision>
    <inertial>
      <origin rpy="0 1.5708 0" xyz="0.11 0 0"/>
      <mass value="1.1"/>
      <inertia ixx="0.004652266666666667" ixy="0.0" ixz="0.0" iyy="0.004652266666666667" iyz="0.0" izz="0.00043120000000000007"/>
    </inertial>
  </link>
  <joint name="right_arm_shoulder_joint" type="revolute">
    <parent link="right_arm_mount_link"/>
    <child link="right_arm_upper_arm_link"/>
    <origin rpy="0 0 0" xyz="0.025 0 0"/>
    <axis xyz="0 -1 0"/>
    <limit effort="22.0" lower="-1.57" upper="1.57" velocity="1.5"/>
    <dynamics damping="0.5" friction="0.12"/>
  </joint>
  <link name="right_arm_forearm_link">
    <visual>
      <origin rpy="0 1.5708 0" xyz="0.10 0 0"/>
      <geometry>
        <cylinder length="0.20" radius="0.024"/>
      </geometry>
      <material name="arm_cyan">
        <color rgba="0.15 0.7 0.8 1.0"/>
      </material>
    </visual>
    <collision>
      <origin rpy="0 1.5708 0" xyz="0.10 0 0"/>
      <geometry>
        <cylinder length="0.20" radius="0.024"/>
      </geometry>
    </collision>
    <inertial>
      <origin rpy="0 1.5708 0" xyz="0.10 0 0"/>
      <mass value="0.8"/>
      <inertia ixx="0.002781866666666667" ixy="0.0" ixz="0.0" iyy="0.002781866666666667" iyz="0.0" izz="0.00023040000000000002"/>
    </inertial>
  </link>
  <joint name="right_arm_elbow_joint" type="revolute">
    <parent link="right_arm_upper_arm_link"/>
    <child link="right_arm_forearm_link"/>
    <origin rpy="0 0 0" xyz="0.22 0 0"/>
    <axis xyz="0 -1 0"/>
    <limit effort="18.0" lower="-2.355" upper="2.355" velocity="1.6"/>
    <dynamics damping="0.4" friction="0.10"/>
  </joint>
  <link name="right_arm_wrist_link">
    <visual>
      <origin rpy="0 1.5708 0" xyz="0.06 0 0"/>
      <geometry>
        <cylinder length="0.12" radius="0.018"/>
      </geometry>
      <material name="arm_blue"/>
    </visual>
    <collision>
      <origin rpy="0 1.5708 0" xyz="0.06 0 0"/>
      <geometry>
        <cylinder length="0.12" radius="0.018"/>
      </geometry>
    </collision>
    <inertial>
      <origin rpy="0 1.5708 0" xyz="0.06 0 0"/>
      <mass value="0.35"/>
      <inertia ixx="0.00044835" ixy="0.0" ixz="0.0" iyy="0.00044835" iyz="0.0" izz="5.669999999999999e-05"/>
    </inertial>
  </link>
  <joint name="right_arm_wrist_joint" type="revolute">
    <parent link="right_arm_forearm_link"/>
    <child link="right_arm_wrist_link"/>
    <origin rpy="0 0 0" xyz="0.20 0 0"/>
    <axis xyz="0 -1 0"/>
    <limit effort="10.0" lower="-1.57" upper="1.57" velocity="2.0"/>
    <dynamics damping="0.25" friction="0.08"/>
  </joint>
  <link name="right_arm_magnet_link">
    <visual>
      <origin rpy="0 1.5708 0" xyz="0.02 0 0"/>
      <geometry>
        <cylinder length="0.03" radius="0.03"/>
      </geometry>
      <material name="magnet_red">
        <color rgba="0.78 0.12 0.12 1.0"/>
      </material>
    </visual>
    <collision>
      <origin rpy="0 1.5708 0" xyz="0.02 0 0"/>
      <geometry>
        <cylinder length="0.03" radius="0.03"/>
      </geometry>
    </collision>
    <inertial>
      <origin rpy="0 1.5708 0" xyz="0.02 0 0"/>
      <mass value="0.15"/>
      <inertia ixx="4.5e-05" ixy="0.0" ixz="0.0" iyy="4.5e-05" iyz="0.0" izz="6.749999999999999e-05"/>
    </inertial>
  </link>
  <joint name="right_arm_magnet_joint" type="fixed">
    <parent link="right_arm_wrist_link"/>
    <child link="right_arm_magnet_link"/>
    <origin rpy="0 0 0" xyz="0.12 0 0"/>
  </joint>
  <link name="camera_link">
    <visual>
      <origin rpy="0 0 0" xyz="0 0 0"/>
      <geometry>
        <box size="0.05 0.04 0.04"/>
      </geometry>
      <material name="camera_black">
        <color rgba="0.1 0.1 0.1 1.0"/>
      </material>
    </visual>
    <collision>
      <origin rpy="0 0 0" xyz="0 0 0"/>
      <geometry>
        <box size="0.05 0.04 0.04"/>
      </geometry>
    </collision>
    <inertial>
      <origin rpy="0 0 0" xyz="0 0 0"/>
      <mass value="0.15"/>
      <inertia ixx="4e-05" ixy="0.0" ixz="0.0" iyy="5.125e-05" iyz="0.0" izz="5.125e-05"/>
    </inertial>
  </link>
  <joint name="camera_joint" type="fixed">
    <parent link="torso_link"/>
    <child link="camera_link"/>
    <origin rpy="0 0 0" xyz="0.29000000000000004 0 0.03"/>
  </joint>
  <link name="lidar_link">
    <visual>
      <origin rpy="0 0 0" xyz="0 0 0"/>
      <geometry>
        <cylinder length="0.04" radius="0.04"/>
      </geometry>
      <material name="lidar_dark">
        <color rgba="0.2 0.2 0.22 1.0"/>
      </material>
    </visual>
    <collision>
      <origin rpy="0 0 0" xyz="0 0 0"/>
      <geometry>
        <cylinder length="0.04" radius="0.04"/>
      </geometry>
    </collision>
    <inertial>
      <origin rpy="0 0 0" xyz="0 0 0"/>
      <mass value="0.2"/>
      <inertia ixx="0.00010666666666666665" ixy="0.0" ixz="0.0" iyy="0.00010666666666666665" iyz="0.0" izz="0.00016"/>
    </inertial>
  </link>
  <joint name="lidar_joint" type="fixed">
    <parent link="torso_link"/>
    <child link="lidar_link"/>
    <origin rpy="0 0 0" xyz="0 0 0.14"/>
  </joint>
  <gazebo reference="chassis-link">
    <material>Gazebo/Blue</material>
    <selfCollide>false</selfCollide>
  </gazebo>
  <gazebo reference="torso_link">
    <material>Gazebo/Silver</material>
    <selfCollide>false</selfCollide>
  </gazebo>
  <gazebo reference="face_panel_link">
    <material>Gazebo/Black</material>
    <selfCollide>false</selfCollide>
  </gazebo>
  <gazebo reference="camera_link">
    <selfCollide>false</selfCollide>
    <sensor name="torso_camera" type="camera">
      <always_on>true</always_on>
      <update_rate>20</update_rate>
      <visualize>true</visualize>
      <topic>camera/image_raw</topic>
      <camera>
        <horizontal_fov>1.3962634</horizontal_fov>
        <image>
          <width>640</width>
          <height>480</height>
          <format>R8G8B8</format>
        </image>
        <clip>
          <near>0.05</near>
          <far>20.0</far>
        </clip>
      </camera>
    </sensor>
  </gazebo>
  <gazebo reference="lidar_link">
    <selfCollide>false</selfCollide>
    <sensor name="torso_lidar" type="gpu_lidar">
      <always_on>true</always_on>
      <update_rate>15</update_rate>
      <visualize>true</visualize>
      <topic>scan</topic>
      <ray>
        <scan>
          <horizontal>
            <samples>640</samples>
            <resolution>1</resolution>
            <min_angle>-3.14159</min_angle>
            <max_angle>3.14159</max_angle>
          </horizontal>
          <vertical>
            <samples>1</samples>
            <resolution>0.01</resolution>
            <min_angle>0.0</min_angle>
            <max_angle>0.0</max_angle>
          </vertical>
        </scan>
        <range>
          <min>0.10</min>
          <max>12.0</max>
          <resolution>0.01</resolution>
        </range>
      </ray>
    </sensor>
  </gazebo>
  <gazebo reference="front_left_wheel_link">
    <material>Gazebo/DarkGrey</material>
    <mu1>1.2</mu1>
    <mu2>1.2</mu2>
    <kp>1000000.0</kp>
    <kd>100.0</kd>
    <minDepth>0.001</minDepth>
    <maxVel>1.0</maxVel>
    <selfCollide>false</selfCollide>
  </gazebo>
  <gazebo reference="front_right_wheel_link">
    <material>Gazebo/DarkGrey</material>
    <mu1>1.2</mu1>
    <mu2>1.2</mu2>
    <kp>1000000.0</kp>
    <kd>100.0</kd>
    <minDepth>0.001</minDepth>
    <maxVel>1.0</maxVel>
    <selfCollide>false</selfCollide>
  </gazebo>
  <gazebo reference="rear_left_wheel_link">
    <material>Gazebo/DarkGrey</material>
    <mu1>1.2</mu1>
    <mu2>1.2</mu2>
    <kp>1000000.0</kp>
    <kd>100.0</kd>
    <minDepth>0.001</minDepth>
    <maxVel>1.0</maxVel>
    <selfCollide>false</selfCollide>
  </gazebo>
  <gazebo reference="rear_right_wheel_link">
    <material>Gazebo/DarkGrey</material>
    <mu1>1.2</mu1>
    <mu2>1.2</mu2>
    <kp>1000000.0</kp>
    <kd>100.0</kd>
    <minDepth>0.001</minDepth>
    <maxVel>1.0</maxVel>
    <selfCollide>false</selfCollide>
  </gazebo>
</robot>
